ERROR:__main__:Uncaught exception
Traceback (most recent call last):
  File "app.py", line 1108, in <module>
    app.run(debug=False)
  File "/Users/andrew/dev/diy-transparency-app/venv/lib/python2.7/site-packages/flask/app.py", line 843, in run
    run_simple(host, port, self, **options)
  File "/Users/andrew/dev/diy-transparency-app/venv/lib/python2.7/site-packages/werkzeug/serving.py", line 694, in run_simple
    inner()
  File "/Users/andrew/dev/diy-transparency-app/venv/lib/python2.7/site-packages/werkzeug/serving.py", line 656, in inner
    fd=fd)
  File "/Users/andrew/dev/diy-transparency-app/venv/lib/python2.7/site-packages/werkzeug/serving.py", line 550, in make_server
    passthrough_errors, ssl_context, fd=fd)
  File "/Users/andrew/dev/diy-transparency-app/venv/lib/python2.7/site-packages/werkzeug/serving.py", line 464, in __init__
    HTTPServer.__init__(self, (host, int(port)), handler)
  File "/System/Library/Frameworks/Python.framework/Versions/2.7/lib/python2.7/SocketServer.py", line 420, in __init__
    self.server_bind()
  File "/System/Library/Frameworks/Python.framework/Versions/2.7/lib/python2.7/BaseHTTPServer.py", line 108, in server_bind
    SocketServer.TCPServer.server_bind(self)
  File "/System/Library/Frameworks/Python.framework/Versions/2.7/lib/python2.7/SocketServer.py", line 434, in server_bind
    self.socket.bind(self.server_address)
  File "/System/Library/Frameworks/Python.framework/Versions/2.7/lib/python2.7/socket.py", line 228, in meth
    return getattr(self._sock,name)(*args)
error: [Errno 48] Address already in use
